Training with a single process on 1 device (cuda:0).
WARNING: No pretrained configuration specified for MONet_T_16 model. Using a default. Please add a config to the model pretrained_cfg registry or pass explicitly.
Model MONet_T_16 created, param count:17492010
Data processing configuration for current model + dataset:
	input_size: (3, 32, 32)
	interpolation: bicubic
	mean: (0.485, 0.456, 0.406)
	std: (0.229, 0.224, 0.225)
	crop_pct: 0.875
	crop_mode: center
Using native Torch AMP. Training in mixed precision.
/home/sharipov/.local/lib/python3.9/site-packages/torch/utils/data/dataloader.py:558: UserWarning: This DataLoader will create 4 worker processes in total. Our suggested max number of worker in current system is 1, which is smaller than what this DataLoader is going to create. Please be aware that excessive worker creation might get DataLoader running slow or even freeze, lower the worker number to avoid potential slowness/freeze if necessary.
  warnings.warn(_create_warning_msg(
Scheduled epochs: 300. LR stepped per epoch.
Traceback (most recent call last):
  File "/home/sharipov/monet/train.py", line 1523, in <module>
    main()
  File "/home/sharipov/monet/train.py", line 1109, in main
    train_metrics = train_one_epoch(
  File "/home/sharipov/monet/train.py", line 1368, in train_one_epoch
    loss, acc1 = _forward()
  File "/home/sharipov/monet/train.py", line 1323, in _forward
    acc1, acc5 = utils.accuracy(output, target, topk=(1,5))
  File "/home/sharipov/monet/timm/utils/metrics.py", line 31, in accuracy
    correct = pred.eq(target.reshape(1, -1).expand_as(pred))
RuntimeError: The expanded size of the tensor (448) must match the existing size (4480) at non-singleton dimension 1.  Target sizes: [5, 448].  Tensor sizes: [1, 4480]
[2024-06-07 20:46:10,248] torch.distributed.elastic.multiprocessing.api: [ERROR] failed (exitcode: 1) local_rank: 0 (pid: 288620) of binary: /usr/bin/python3
Traceback (most recent call last):
  File "/home/sharipov/.local/bin/torchrun", line 8, in <module>
    sys.exit(main())
  File "/home/sharipov/.local/lib/python3.9/site-packages/torch/distributed/elastic/multiprocessing/errors/__init__.py", line 347, in wrapper
    return f(*args, **kwargs)
  File "/home/sharipov/.local/lib/python3.9/site-packages/torch/distributed/run.py", line 812, in main
    run(args)
  File "/home/sharipov/.local/lib/python3.9/site-packages/torch/distributed/run.py", line 803, in run
    elastic_launch(
  File "/home/sharipov/.local/lib/python3.9/site-packages/torch/distributed/launcher/api.py", line 135, in __call__
    return launch_agent(self._config, self._entrypoint, list(args))
  File "/home/sharipov/.local/lib/python3.9/site-packages/torch/distributed/launcher/api.py", line 268, in launch_agent
    raise ChildFailedError(
torch.distributed.elastic.multiprocessing.errors.ChildFailedError: 
============================================================
train.py FAILED
------------------------------------------------------------
Failures:
  <NO_OTHER_FAILURES>
------------------------------------------------------------
Root Cause (first observed failure):
[0]:
  time      : 2024-06-07_20:46:10
  host      : i19.izar.cluster
  rank      : 0 (local_rank: 0)
  exitcode  : 1 (pid: 288620)
  error_file: <N/A>
  traceback : To enable traceback see: https://pytorch.org/docs/stable/elastic/errors.html
============================================================
