Training with a single process on 1 device (cuda:0).
WARNING: No pretrained configuration specified for MONet_T_16_double model. Using a default. Please add a config to the model pretrained_cfg registry or pass explicitly.
Model MONet_T_16_double created, param count:17509380
Data processing configuration for current model + dataset:
	input_size: (3, 224, 224)
	interpolation: bicubic
	mean: (0.485, 0.456, 0.406)
	std: (0.229, 0.224, 0.225)
	crop_pct: 0.875
	crop_mode: center
Using native Torch AMP. Training in mixed precision.
/home/sharipov/.local/lib/python3.9/site-packages/torch/utils/data/dataloader.py:558: UserWarning: This DataLoader will create 4 worker processes in total. Our suggested max number of worker in current system is 1, which is smaller than what this DataLoader is going to create. Please be aware that excessive worker creation might get DataLoader running slow or even freeze, lower the worker number to avoid potential slowness/freeze if necessary.
  warnings.warn(_create_warning_msg(
Scheduled epochs: 450. LR stepped per epoch.
Traceback (most recent call last):
  File "/home/sharipov/monet/train.py", line 1515, in <module>
    main()
  File "/home/sharipov/monet/train.py", line 1109, in main
    train_metrics = train_one_epoch(
  File "/home/sharipov/monet/train.py", line 1360, in train_one_epoch
    loss, acc1 = _forward()
  File "/home/sharipov/monet/train.py", line 1315, in _forward
    output = model(input)
  File "/home/sharipov/.local/lib/python3.9/site-packages/torch/nn/modules/module.py", line 1511, in _wrapped_call_impl
    return self._call_impl(*args, **kwargs)
  File "/home/sharipov/.local/lib/python3.9/site-packages/torch/nn/modules/module.py", line 1520, in _call_impl
    return forward_call(*args, **kwargs)
  File "/home/sharipov/monet/timm/models/monet.py", line 526, in forward
    else: x1 = layer[0](x1, current_residual)
  File "/home/sharipov/.local/lib/python3.9/site-packages/torch/nn/modules/module.py", line 1511, in _wrapped_call_impl
    return self._call_impl(*args, **kwargs)
  File "/home/sharipov/.local/lib/python3.9/site-packages/torch/nn/modules/module.py", line 1520, in _call_impl
    return forward_call(*args, **kwargs)
  File "/home/sharipov/monet/timm/models/monet.py", line 110, in forward
    z = self.mlp2(z)
  File "/home/sharipov/.local/lib/python3.9/site-packages/torch/nn/modules/module.py", line 1511, in _wrapped_call_impl
    return self._call_impl(*args, **kwargs)
  File "/home/sharipov/.local/lib/python3.9/site-packages/torch/nn/modules/module.py", line 1520, in _call_impl
    return forward_call(*args, **kwargs)
  File "/home/sharipov/monet/timm/layers/mlp.py", line 561, in forward
    out1 = out1 + self.alpha * out_so
torch.cuda.OutOfMemoryError: CUDA out of memory. Tried to allocate 3.02 GiB. GPU 0 has a total capacity of 31.74 GiB of which 1.48 GiB is free. Including non-PyTorch memory, this process has 30.26 GiB memory in use. Of the allocated memory 29.67 GiB is allocated by PyTorch, and 194.19 MiB is reserved by PyTorch but unallocated. If reserved but unallocated memory is large try setting PYTORCH_CUDA_ALLOC_CONF=expandable_segments:True to avoid fragmentation.  See documentation for Memory Management  (https://pytorch.org/docs/stable/notes/cuda.html#environment-variables)
[2024-06-07 21:28:17,072] torch.distributed.elastic.multiprocessing.api: [ERROR] failed (exitcode: 1) local_rank: 0 (pid: 297400) of binary: /usr/bin/python3
Traceback (most recent call last):
  File "/home/sharipov/.local/bin/torchrun", line 8, in <module>
    sys.exit(main())
  File "/home/sharipov/.local/lib/python3.9/site-packages/torch/distributed/elastic/multiprocessing/errors/__init__.py", line 347, in wrapper
    return f(*args, **kwargs)
  File "/home/sharipov/.local/lib/python3.9/site-packages/torch/distributed/run.py", line 812, in main
    run(args)
  File "/home/sharipov/.local/lib/python3.9/site-packages/torch/distributed/run.py", line 803, in run
    elastic_launch(
  File "/home/sharipov/.local/lib/python3.9/site-packages/torch/distributed/launcher/api.py", line 135, in __call__
    return launch_agent(self._config, self._entrypoint, list(args))
  File "/home/sharipov/.local/lib/python3.9/site-packages/torch/distributed/launcher/api.py", line 268, in launch_agent
    raise ChildFailedError(
torch.distributed.elastic.multiprocessing.errors.ChildFailedError: 
============================================================
train.py FAILED
------------------------------------------------------------
Failures:
  <NO_OTHER_FAILURES>
------------------------------------------------------------
Root Cause (first observed failure):
[0]:
  time      : 2024-06-07_21:28:17
  host      : i19.izar.cluster
  rank      : 0 (local_rank: 0)
  exitcode  : 1 (pid: 297400)
  error_file: <N/A>
  traceback : To enable traceback see: https://pytorch.org/docs/stable/elastic/errors.html
============================================================
