Training with a single process on 1 device (cuda:0).
WARNING: No pretrained configuration specified for MONet_T_16 model. Using a default. Please add a config to the model pretrained_cfg registry or pass explicitly.
Model MONet_T_16 created, param count:17492010
Data processing configuration for current model + dataset:
	input_size: (3, 32, 32)
	interpolation: bicubic
	mean: (0.485, 0.456, 0.406)
	std: (0.229, 0.224, 0.225)
	crop_pct: 0.875
	crop_mode: center
AMP not enabled. Training in float32.
Traceback (most recent call last):
  File "/home/sharipov/monet/train.py", line 1523, in <module>
    main()
  File "/home/sharipov/monet/train.py", line 615, in main
    dataset_train = create_dataset(
  File "/home/sharipov/monet/timm/data/dataset_factory.py", line 203, in create_dataset
    ds = ds_class(train=use_train, validation=validation,  **torch_kwargs)
TypeError: __init__() got an unexpected keyword argument 'validation'
[2024-06-07 19:27:31,759] torch.distributed.elastic.multiprocessing.api: [ERROR] failed (exitcode: 1) local_rank: 0 (pid: 3530090) of binary: /usr/bin/python3
Traceback (most recent call last):
  File "/home/sharipov/.local/bin/torchrun", line 8, in <module>
    sys.exit(main())
  File "/home/sharipov/.local/lib/python3.9/site-packages/torch/distributed/elastic/multiprocessing/errors/__init__.py", line 347, in wrapper
    return f(*args, **kwargs)
  File "/home/sharipov/.local/lib/python3.9/site-packages/torch/distributed/run.py", line 812, in main
    run(args)
  File "/home/sharipov/.local/lib/python3.9/site-packages/torch/distributed/run.py", line 803, in run
    elastic_launch(
  File "/home/sharipov/.local/lib/python3.9/site-packages/torch/distributed/launcher/api.py", line 135, in __call__
    return launch_agent(self._config, self._entrypoint, list(args))
  File "/home/sharipov/.local/lib/python3.9/site-packages/torch/distributed/launcher/api.py", line 268, in launch_agent
    raise ChildFailedError(
torch.distributed.elastic.multiprocessing.errors.ChildFailedError: 
============================================================
train.py FAILED
------------------------------------------------------------
Failures:
  <NO_OTHER_FAILURES>
------------------------------------------------------------
Root Cause (first observed failure):
[0]:
  time      : 2024-06-07_19:27:31
  host      : i14.izar.cluster
  rank      : 0 (local_rank: 0)
  exitcode  : 1 (pid: 3530090)
  error_file: <N/A>
  traceback : To enable traceback see: https://pytorch.org/docs/stable/elastic/errors.html
============================================================
