Training with a single process on 1 device (cuda:0).
WARNING: No pretrained configuration specified for MONet_T model. Using a default. Please add a config to the model pretrained_cfg registry or pass explicitly.
Model MONet_T created, param count:19493390
Data processing configuration for current model + dataset:
	input_size: (3, 32, 32)
	interpolation: bicubic
	mean: (0.485, 0.456, 0.406)
	std: (0.229, 0.224, 0.225)
	crop_pct: 0.875
	crop_mode: center
AMP not enabled. Training in float32.
/home/sharipov/monet/venv/lib64/python3.9/site-packages/torch/utils/data/dataloader.py:558: UserWarning: This DataLoader will create 4 worker processes in total. Our suggested max number of worker in current system is 1, which is smaller than what this DataLoader is going to create. Please be aware that excessive worker creation might get DataLoader running slow or even freeze, lower the worker number to avoid potential slowness/freeze if necessary.
  warnings.warn(_create_warning_msg(
Scheduled epochs: 300. LR stepped per epoch.
Traceback (most recent call last):
  File "/home/sharipov/monet/train.py", line 1268, in <module>
    main()
  File "/home/sharipov/monet/train.py", line 933, in main
    train_metrics = train_one_epoch(
  File "/home/sharipov/monet/train.py", line 1128, in train_one_epoch
    loss = _forward()
  File "/home/sharipov/monet/train.py", line 1092, in _forward
    output = model(input)
  File "/home/sharipov/monet/venv/lib64/python3.9/site-packages/torch/nn/modules/module.py", line 1511, in _wrapped_call_impl
    return self._call_impl(*args, **kwargs)
  File "/home/sharipov/monet/venv/lib64/python3.9/site-packages/torch/nn/modules/module.py", line 1520, in _call_impl
    return forward_call(*args, **kwargs)
  File "/home/sharipov/monet/timm/models/monet.py", line 212, in forward
    out = self.head(x1)
  File "/home/sharipov/monet/venv/lib64/python3.9/site-packages/torch/nn/modules/module.py", line 1511, in _wrapped_call_impl
    return self._call_impl(*args, **kwargs)
  File "/home/sharipov/monet/venv/lib64/python3.9/site-packages/torch/nn/modules/module.py", line 1520, in _call_impl
    return forward_call(*args, **kwargs)
  File "/home/sharipov/monet/venv/lib64/python3.9/site-packages/torch/nn/modules/container.py", line 217, in forward
    input = module(input)
  File "/home/sharipov/monet/venv/lib64/python3.9/site-packages/torch/nn/modules/module.py", line 1511, in _wrapped_call_impl
    return self._call_impl(*args, **kwargs)
  File "/home/sharipov/monet/venv/lib64/python3.9/site-packages/torch/nn/modules/module.py", line 1520, in _call_impl
    return forward_call(*args, **kwargs)
  File "/home/sharipov/monet/venv/lib64/python3.9/site-packages/torch/nn/modules/linear.py", line 116, in forward
    return F.linear(input, self.weight, self.bias)
RuntimeError: mat1 and mat2 shapes cannot be multiplied (64x64 and 192x10)
[2024-04-23 03:47:22,826] torch.distributed.elastic.multiprocessing.api: [ERROR] failed (exitcode: 1) local_rank: 0 (pid: 13734) of binary: /home/sharipov/monet/venv/bin/python
Traceback (most recent call last):
  File "/home/sharipov/monet/venv/bin/torchrun", line 8, in <module>
    sys.exit(main())
  File "/home/sharipov/monet/venv/lib64/python3.9/site-packages/torch/distributed/elastic/multiprocessing/errors/__init__.py", line 347, in wrapper
    return f(*args, **kwargs)
  File "/home/sharipov/monet/venv/lib64/python3.9/site-packages/torch/distributed/run.py", line 812, in main
    run(args)
  File "/home/sharipov/monet/venv/lib64/python3.9/site-packages/torch/distributed/run.py", line 803, in run
    elastic_launch(
  File "/home/sharipov/monet/venv/lib64/python3.9/site-packages/torch/distributed/launcher/api.py", line 135, in __call__
    return launch_agent(self._config, self._entrypoint, list(args))
  File "/home/sharipov/monet/venv/lib64/python3.9/site-packages/torch/distributed/launcher/api.py", line 268, in launch_agent
    raise ChildFailedError(
torch.distributed.elastic.multiprocessing.errors.ChildFailedError: 
============================================================
train.py FAILED
------------------------------------------------------------
Failures:
  <NO_OTHER_FAILURES>
------------------------------------------------------------
Root Cause (first observed failure):
[0]:
  time      : 2024-04-23_03:47:22
  host      : i11.izar.cluster
  rank      : 0 (local_rank: 0)
  exitcode  : 1 (pid: 13734)
  error_file: <N/A>
  traceback : To enable traceback see: https://pytorch.org/docs/stable/elastic/errors.html
============================================================
