Training with a single process on 1 device (cuda:0).
WARNING: No pretrained configuration specified for MONet_T_variable model. Using a default. Please add a config to the model pretrained_cfg registry or pass explicitly.
Traceback (most recent call last):
  File "/home/sharipov/monet/train.py", line 1083, in <module>
    main()
  File "/home/sharipov/monet/train.py", line 431, in main
    model = create_model(
  File "/home/sharipov/monet/timm/models/_factory.py", line 117, in create_model
    model = create_fn(
  File "/home/sharipov/monet/timm/models/monet.py", line 349, in MONet_T_variable
    model = _create_improved_MONet('MONet_T_variable', pretrained=pretrained, **model_args)
  File "/home/sharipov/monet/timm/models/monet.py", line 249, in _create_improved_MONet
    model = build_model_with_cfg(
  File "/home/sharipov/monet/timm/models/_builder.py", line 385, in build_model_with_cfg
    model = model_cls(**kwargs)
  File "/home/sharipov/monet/timm/models/monet.py", line 166, in __init__
    network.append(Downsample(embed_dim[i], embed_dim[i+1], patch_size))
  File "/home/sharipov/monet/timm/models/monet.py", line 97, in __init__
    assert patch_size == 2, patch_size
AssertionError: 1
[2024-03-16 11:15:16,001] torch.distributed.elastic.multiprocessing.api: [ERROR] failed (exitcode: 1) local_rank: 0 (pid: 1511671) of binary: /home/sharipov/monet/venv/bin/python
Traceback (most recent call last):
  File "/home/sharipov/monet/venv/bin/torchrun", line 8, in <module>
    sys.exit(main())
  File "/home/sharipov/monet/venv/lib64/python3.9/site-packages/torch/distributed/elastic/multiprocessing/errors/__init__.py", line 347, in wrapper
    return f(*args, **kwargs)
  File "/home/sharipov/monet/venv/lib64/python3.9/site-packages/torch/distributed/run.py", line 812, in main
    run(args)
  File "/home/sharipov/monet/venv/lib64/python3.9/site-packages/torch/distributed/run.py", line 803, in run
    elastic_launch(
  File "/home/sharipov/monet/venv/lib64/python3.9/site-packages/torch/distributed/launcher/api.py", line 135, in __call__
    return launch_agent(self._config, self._entrypoint, list(args))
  File "/home/sharipov/monet/venv/lib64/python3.9/site-packages/torch/distributed/launcher/api.py", line 268, in launch_agent
    raise ChildFailedError(
torch.distributed.elastic.multiprocessing.errors.ChildFailedError: 
============================================================
train.py FAILED
------------------------------------------------------------
Failures:
  <NO_OTHER_FAILURES>
------------------------------------------------------------
Root Cause (first observed failure):
[0]:
  time      : 2024-03-16_11:15:16
  host      : i67.izar.cluster
  rank      : 0 (local_rank: 0)
  exitcode  : 1 (pid: 1511671)
  error_file: <N/A>
  traceback : To enable traceback see: https://pytorch.org/docs/stable/elastic/errors.html
============================================================
